[2024-06-16T19:31:07.373+0000] {taskinstance.py:1157} INFO - Dependencies all met for dep_context=non-requeueable deps ti=<TaskInstance: unique_name_of_this_dag.list_keys manual__2024-06-16T19:31:06.420330+00:00 [queued]>
[2024-06-16T19:31:07.381+0000] {taskinstance.py:1157} INFO - Dependencies all met for dep_context=requeueable deps ti=<TaskInstance: unique_name_of_this_dag.list_keys manual__2024-06-16T19:31:06.420330+00:00 [queued]>
[2024-06-16T19:31:07.381+0000] {taskinstance.py:1359} INFO - Starting attempt 1 of 1
[2024-06-16T19:31:07.392+0000] {taskinstance.py:1380} INFO - Executing <Task(PythonOperator): list_keys> on 2024-06-16 19:31:06.420330+00:00
[2024-06-16T19:31:07.399+0000] {standard_task_runner.py:57} INFO - Started process 3640 to run task
[2024-06-16T19:31:07.403+0000] {standard_task_runner.py:84} INFO - Running: ['***', 'tasks', 'run', 'unique_name_of_this_dag', 'list_keys', 'manual__2024-06-16T19:31:06.420330+00:00', '--job-id', '29', '--raw', '--subdir', 'DAGS_FOLDER/test_dag.py', '--cfg-path', '/tmp/tmpb442kt4q']
[2024-06-16T19:31:07.404+0000] {standard_task_runner.py:85} INFO - Job 29: Subtask list_keys
[2024-06-16T19:31:07.458+0000] {task_command.py:415} INFO - Running <TaskInstance: unique_name_of_this_dag.list_keys manual__2024-06-16T19:31:06.420330+00:00 [running]> on host 52e246c9d923
[2024-06-16T19:31:07.533+0000] {taskinstance.py:1660} INFO - Exporting env vars: AIRFLOW_CTX_DAG_OWNER='***' AIRFLOW_CTX_DAG_ID='unique_name_of_this_dag' AIRFLOW_CTX_TASK_ID='list_keys' AIRFLOW_CTX_EXECUTION_DATE='2024-06-16T19:31:06.420330+00:00' AIRFLOW_CTX_TRY_NUMBER='1' AIRFLOW_CTX_DAG_RUN_ID='manual__2024-06-16T19:31:06.420330+00:00'
[2024-06-16T19:31:07.534+0000] {taskinstance.py:1935} ERROR - Task failed with exception
Traceback (most recent call last):
  File "/home/airflow/.local/lib/python3.8/site-packages/airflow/operators/python.py", line 192, in execute
    return_value = self.execute_callable()
  File "/home/airflow/.local/lib/python3.8/site-packages/airflow/operators/python.py", line 209, in execute_callable
    return self.python_callable(*self.op_args, **self.op_kwargs)
  File "/opt/airflow/dags/test_dag.py", line 27, in list_keys
    logging.info(f"Listing Keys from {bucket}/{prefix}")
NameError: name 'bucket' is not defined
[2024-06-16T19:31:07.542+0000] {taskinstance.py:1398} INFO - Marking task as FAILED. dag_id=unique_name_of_this_dag, task_id=list_keys, execution_date=20240616T193106, start_date=20240616T193107, end_date=20240616T193107
[2024-06-16T19:31:07.552+0000] {standard_task_runner.py:104} ERROR - Failed to execute job 29 for task list_keys (name 'bucket' is not defined; 3640)
[2024-06-16T19:31:07.574+0000] {local_task_job_runner.py:228} INFO - Task exited with return code 1
[2024-06-16T19:31:07.589+0000] {taskinstance.py:2776} INFO - 0 downstream tasks scheduled from follow-on schedule check
